Performing system checks...

System check identified no issues (0 silenced).
January 10, 2020 - 07:40:58
Django version 2.2.5, using settings 'signature.settings'
Starting ASGI/Channels version 2.1.7 development server at http://127.0.0.1:5001/
Quit the server with CONTROL-C.
Performing system checks...

System check identified no issues (0 silenced).
January 11, 2020 - 08:43:51
Django version 2.2.5, using settings 'signature.settings'
Starting ASGI/Channels version 2.1.7 development server at http://127.0.0.1:5001/
Quit the server with CONTROL-C.
Performing system checks...

System check identified no issues (0 silenced).
January 11, 2020 - 08:43:53
Django version 2.2.5, using settings 'signature.settings'
Starting ASGI/Channels version 2.1.7 development server at http://127.0.0.1:5001/
Quit the server with CONTROL-C.
Performing system checks...

System check identified no issues (0 silenced).
January 11, 2020 - 09:20:23
Django version 2.2.5, using settings 'signature.settings'
Starting ASGI/Channels version 2.1.7 development server at http://127.0.0.1:5001/
Quit the server with CONTROL-C.
Performing system checks...

System check identified no issues (0 silenced).
January 11, 2020 - 09:29:55
Django version 2.2.5, using settings 'signature.settings'
Starting ASGI/Channels version 2.1.7 development server at http://127.0.0.1:5001/
Quit the server with CONTROL-C.
Exception in thread django-main-thread:
Traceback (most recent call last):
  File "/usr/local/Cellar/python/3.7.5/Frameworks/Python.framework/Versions/3.7/lib/python3.7/threading.py", line 926, in _bootstrap_inner
    self.run()
  File "/usr/local/Cellar/python/3.7.5/Frameworks/Python.framework/Versions/3.7/lib/python3.7/threading.py", line 870, in run
    self._target(*self._args, **self._kwargs)
  File "/Users/mac/Desktop/sa-manage/super/lib/python3.7/site-packages/django/utils/autoreload.py", line 54, in wrapper
    fn(*args, **kwargs)
  File "/Users/mac/Desktop/sa-manage/super/lib/python3.7/site-packages/django/core/management/commands/runserver.py", line 109, in inner_run
    autoreload.raise_last_exception()
  File "/Users/mac/Desktop/sa-manage/super/lib/python3.7/site-packages/django/utils/autoreload.py", line 77, in raise_last_exception
    raise _exception[1]
  File "/Users/mac/Desktop/sa-manage/super/lib/python3.7/site-packages/django/core/management/__init__.py", line 337, in execute
    autoreload.check_errors(django.setup)()
  File "/Users/mac/Desktop/sa-manage/super/lib/python3.7/site-packages/django/utils/autoreload.py", line 54, in wrapper
    fn(*args, **kwargs)
  File "/Users/mac/Desktop/sa-manage/super/lib/python3.7/site-packages/django/__init__.py", line 24, in setup
    apps.populate(settings.INSTALLED_APPS)
  File "/Users/mac/Desktop/sa-manage/super/lib/python3.7/site-packages/django/apps/registry.py", line 114, in populate
    app_config.import_models()
  File "/Users/mac/Desktop/sa-manage/super/lib/python3.7/site-packages/django/apps/config.py", line 211, in import_models
    self.models_module = import_module(models_module_name)
  File "/Users/mac/Desktop/sa-manage/super/lib/python3.7/importlib/__init__.py", line 127, in import_module
    return _bootstrap._gcd_import(name[level:], package, level)
  File "<frozen importlib._bootstrap>", line 1006, in _gcd_import
  File "<frozen importlib._bootstrap>", line 983, in _find_and_load
  File "<frozen importlib._bootstrap>", line 967, in _find_and_load_unlocked
  File "<frozen importlib._bootstrap>", line 677, in _load_unlocked
  File "<frozen importlib._bootstrap_external>", line 728, in exec_module
  File "<frozen importlib._bootstrap>", line 219, in _call_with_frames_removed
  File "/Users/mac/Desktop/sa-manage/super/signature/apple/models.py", line 4, in <module>
    class AppleAccountTb(models.Model):
  File "/Users/mac/Desktop/sa-manage/super/signature/apple/models.py", line 11, in AppleAccountTb
    mod_date  = models.DateTimeField('解析最后修改日期', default=timezone.now)
NameError: name 'timezone' is not defined

Exception in thread django-main-thread:
Traceback (most recent call last):
  File "/usr/local/Cellar/python/3.7.5/Frameworks/Python.framework/Versions/3.7/lib/python3.7/threading.py", line 926, in _bootstrap_inner
    self.run()
  File "/usr/local/Cellar/python/3.7.5/Frameworks/Python.framework/Versions/3.7/lib/python3.7/threading.py", line 870, in run
    self._target(*self._args, **self._kwargs)
  File "/Users/mac/Desktop/sa-manage/super/lib/python3.7/site-packages/django/utils/autoreload.py", line 54, in wrapper
    fn(*args, **kwargs)
  File "/Users/mac/Desktop/sa-manage/super/lib/python3.7/site-packages/django/core/management/commands/runserver.py", line 109, in inner_run
    autoreload.raise_last_exception()
  File "/Users/mac/Desktop/sa-manage/super/lib/python3.7/site-packages/django/utils/autoreload.py", line 77, in raise_last_exception
    raise _exception[1]
  File "/Users/mac/Desktop/sa-manage/super/lib/python3.7/site-packages/django/core/management/__init__.py", line 337, in execute
    autoreload.check_errors(django.setup)()
  File "/Users/mac/Desktop/sa-manage/super/lib/python3.7/site-packages/django/utils/autoreload.py", line 54, in wrapper
    fn(*args, **kwargs)
  File "/Users/mac/Desktop/sa-manage/super/lib/python3.7/site-packages/django/__init__.py", line 24, in setup
    apps.populate(settings.INSTALLED_APPS)
  File "/Users/mac/Desktop/sa-manage/super/lib/python3.7/site-packages/django/apps/registry.py", line 114, in populate
    app_config.import_models()
  File "/Users/mac/Desktop/sa-manage/super/lib/python3.7/site-packages/django/apps/config.py", line 211, in import_models
    self.models_module = import_module(models_module_name)
  File "/Users/mac/Desktop/sa-manage/super/lib/python3.7/importlib/__init__.py", line 127, in import_module
    return _bootstrap._gcd_import(name[level:], package, level)
  File "<frozen importlib._bootstrap>", line 1006, in _gcd_import
  File "<frozen importlib._bootstrap>", line 983, in _find_and_load
  File "<frozen importlib._bootstrap>", line 967, in _find_and_load_unlocked
  File "<frozen importlib._bootstrap>", line 677, in _load_unlocked
  File "<frozen importlib._bootstrap_external>", line 728, in exec_module
  File "<frozen importlib._bootstrap>", line 219, in _call_with_frames_removed
  File "/Users/mac/Desktop/sa-manage/super/signature/apple/models.py", line 4, in <module>
    class AppleAccountTb(models.Model):
  File "/Users/mac/Desktop/sa-manage/super/signature/apple/models.py", line 11, in AppleAccountTb
    mod_date  = models.DateTimeField('解析最后修改日期', default=timezone.now)
NameError: name 'timezone' is not defined

Exception in thread django-main-thread:
Traceback (most recent call last):
  File "/usr/local/Cellar/python/3.7.5/Frameworks/Python.framework/Versions/3.7/lib/python3.7/threading.py", line 926, in _bootstrap_inner
    self.run()
  File "/usr/local/Cellar/python/3.7.5/Frameworks/Python.framework/Versions/3.7/lib/python3.7/threading.py", line 870, in run
    self._target(*self._args, **self._kwargs)
  File "/Users/mac/Desktop/sa-manage/super/lib/python3.7/site-packages/django/utils/autoreload.py", line 54, in wrapper
    fn(*args, **kwargs)
  File "/Users/mac/Desktop/sa-manage/super/lib/python3.7/site-packages/django/core/management/commands/runserver.py", line 109, in inner_run
    autoreload.raise_last_exception()
  File "/Users/mac/Desktop/sa-manage/super/lib/python3.7/site-packages/django/utils/autoreload.py", line 77, in raise_last_exception
    raise _exception[1]
  File "/Users/mac/Desktop/sa-manage/super/lib/python3.7/site-packages/django/core/management/__init__.py", line 337, in execute
    autoreload.check_errors(django.setup)()
  File "/Users/mac/Desktop/sa-manage/super/lib/python3.7/site-packages/django/utils/autoreload.py", line 54, in wrapper
    fn(*args, **kwargs)
  File "/Users/mac/Desktop/sa-manage/super/lib/python3.7/site-packages/django/__init__.py", line 24, in setup
    apps.populate(settings.INSTALLED_APPS)
  File "/Users/mac/Desktop/sa-manage/super/lib/python3.7/site-packages/django/apps/registry.py", line 114, in populate
    app_config.import_models()
  File "/Users/mac/Desktop/sa-manage/super/lib/python3.7/site-packages/django/apps/config.py", line 211, in import_models
    self.models_module = import_module(models_module_name)
  File "/Users/mac/Desktop/sa-manage/super/lib/python3.7/importlib/__init__.py", line 127, in import_module
    return _bootstrap._gcd_import(name[level:], package, level)
  File "<frozen importlib._bootstrap>", line 1006, in _gcd_import
  File "<frozen importlib._bootstrap>", line 983, in _find_and_load
  File "<frozen importlib._bootstrap>", line 967, in _find_and_load_unlocked
  File "<frozen importlib._bootstrap>", line 677, in _load_unlocked
  File "<frozen importlib._bootstrap_external>", line 728, in exec_module
  File "<frozen importlib._bootstrap>", line 219, in _call_with_frames_removed
  File "/Users/mac/Desktop/sa-manage/super/signature/apple/models.py", line 4, in <module>
    class AppleAccountTb(models.Model):
  File "/Users/mac/Desktop/sa-manage/super/signature/apple/models.py", line 11, in AppleAccountTb
    mod_date  = models.DateTimeField('解析最后修改日期', default=timezone.now)
NameError: name 'timezone' is not defined

Exception in thread django-main-thread:
Traceback (most recent call last):
  File "/usr/local/Cellar/python/3.7.5/Frameworks/Python.framework/Versions/3.7/lib/python3.7/threading.py", line 926, in _bootstrap_inner
    self.run()
  File "/usr/local/Cellar/python/3.7.5/Frameworks/Python.framework/Versions/3.7/lib/python3.7/threading.py", line 870, in run
    self._target(*self._args, **self._kwargs)
  File "/Users/mac/Desktop/sa-manage/super/lib/python3.7/site-packages/django/utils/autoreload.py", line 54, in wrapper
    fn(*args, **kwargs)
  File "/Users/mac/Desktop/sa-manage/super/lib/python3.7/site-packages/django/core/management/commands/runserver.py", line 109, in inner_run
    autoreload.raise_last_exception()
  File "/Users/mac/Desktop/sa-manage/super/lib/python3.7/site-packages/django/utils/autoreload.py", line 77, in raise_last_exception
    raise _exception[1]
  File "/Users/mac/Desktop/sa-manage/super/lib/python3.7/site-packages/django/core/management/__init__.py", line 337, in execute
    autoreload.check_errors(django.setup)()
  File "/Users/mac/Desktop/sa-manage/super/lib/python3.7/site-packages/django/utils/autoreload.py", line 54, in wrapper
    fn(*args, **kwargs)
  File "/Users/mac/Desktop/sa-manage/super/lib/python3.7/site-packages/django/__init__.py", line 24, in setup
    apps.populate(settings.INSTALLED_APPS)
  File "/Users/mac/Desktop/sa-manage/super/lib/python3.7/site-packages/django/apps/registry.py", line 114, in populate
    app_config.import_models()
  File "/Users/mac/Desktop/sa-manage/super/lib/python3.7/site-packages/django/apps/config.py", line 211, in import_models
    self.models_module = import_module(models_module_name)
  File "/Users/mac/Desktop/sa-manage/super/lib/python3.7/importlib/__init__.py", line 127, in import_module
    return _bootstrap._gcd_import(name[level:], package, level)
  File "<frozen importlib._bootstrap>", line 1006, in _gcd_import
  File "<frozen importlib._bootstrap>", line 983, in _find_and_load
  File "<frozen importlib._bootstrap>", line 967, in _find_and_load_unlocked
  File "<frozen importlib._bootstrap>", line 677, in _load_unlocked
  File "<frozen importlib._bootstrap_external>", line 728, in exec_module
  File "<frozen importlib._bootstrap>", line 219, in _call_with_frames_removed
  File "/Users/mac/Desktop/sa-manage/super/signature/apple/models.py", line 4, in <module>
    class AppleAccountTb(models.Model):
  File "/Users/mac/Desktop/sa-manage/super/signature/apple/models.py", line 13, in AppleAccountTb
    mod_date  = models.DateTimeField('解析最后修改日期', default=timezone.now)
NameError: name 'timezone' is not defined

Exception in thread django-main-thread:
Traceback (most recent call last):
  File "/usr/local/Cellar/python/3.7.5/Frameworks/Python.framework/Versions/3.7/lib/python3.7/threading.py", line 926, in _bootstrap_inner
    self.run()
  File "/usr/local/Cellar/python/3.7.5/Frameworks/Python.framework/Versions/3.7/lib/python3.7/threading.py", line 870, in run
    self._target(*self._args, **self._kwargs)
  File "/Users/mac/Desktop/sa-manage/super/lib/python3.7/site-packages/django/utils/autoreload.py", line 54, in wrapper
    fn(*args, **kwargs)
  File "/Users/mac/Desktop/sa-manage/super/lib/python3.7/site-packages/django/core/management/commands/runserver.py", line 109, in inner_run
    autoreload.raise_last_exception()
  File "/Users/mac/Desktop/sa-manage/super/lib/python3.7/site-packages/django/utils/autoreload.py", line 77, in raise_last_exception
    raise _exception[1]
  File "/Users/mac/Desktop/sa-manage/super/lib/python3.7/site-packages/django/core/management/__init__.py", line 337, in execute
    autoreload.check_errors(django.setup)()
  File "/Users/mac/Desktop/sa-manage/super/lib/python3.7/site-packages/django/utils/autoreload.py", line 54, in wrapper
    fn(*args, **kwargs)
  File "/Users/mac/Desktop/sa-manage/super/lib/python3.7/site-packages/django/__init__.py", line 24, in setup
    apps.populate(settings.INSTALLED_APPS)
  File "/Users/mac/Desktop/sa-manage/super/lib/python3.7/site-packages/django/apps/registry.py", line 114, in populate
    app_config.import_models()
  File "/Users/mac/Desktop/sa-manage/super/lib/python3.7/site-packages/django/apps/config.py", line 211, in import_models
    self.models_module = import_module(models_module_name)
  File "/Users/mac/Desktop/sa-manage/super/lib/python3.7/importlib/__init__.py", line 127, in import_module
    return _bootstrap._gcd_import(name[level:], package, level)
  File "<frozen importlib._bootstrap>", line 1006, in _gcd_import
  File "<frozen importlib._bootstrap>", line 983, in _find_and_load
  File "<frozen importlib._bootstrap>", line 967, in _find_and_load_unlocked
  File "<frozen importlib._bootstrap>", line 677, in _load_unlocked
  File "<frozen importlib._bootstrap_external>", line 728, in exec_module
  File "<frozen importlib._bootstrap>", line 219, in _call_with_frames_removed
  File "/Users/mac/Desktop/sa-manage/super/signature/apple/models.py", line 4, in <module>
    class AppleAccountTb(models.Model):
  File "/Users/mac/Desktop/sa-manage/super/signature/apple/models.py", line 13, in AppleAccountTb
    create_time = models.DateTimeField("生成的日期", default=timezone.now)
NameError: name 'timezone' is not defined

Exception in thread django-main-thread:
Traceback (most recent call last):
  File "/usr/local/Cellar/python/3.7.5/Frameworks/Python.framework/Versions/3.7/lib/python3.7/threading.py", line 926, in _bootstrap_inner
    self.run()
  File "/usr/local/Cellar/python/3.7.5/Frameworks/Python.framework/Versions/3.7/lib/python3.7/threading.py", line 870, in run
    self._target(*self._args, **self._kwargs)
  File "/Users/mac/Desktop/sa-manage/super/lib/python3.7/site-packages/django/utils/autoreload.py", line 54, in wrapper
    fn(*args, **kwargs)
  File "/Users/mac/Desktop/sa-manage/super/lib/python3.7/site-packages/django/core/management/commands/runserver.py", line 109, in inner_run
    autoreload.raise_last_exception()
  File "/Users/mac/Desktop/sa-manage/super/lib/python3.7/site-packages/django/utils/autoreload.py", line 77, in raise_last_exception
    raise _exception[1]
  File "/Users/mac/Desktop/sa-manage/super/lib/python3.7/site-packages/django/core/management/__init__.py", line 337, in execute
    autoreload.check_errors(django.setup)()
  File "/Users/mac/Desktop/sa-manage/super/lib/python3.7/site-packages/django/utils/autoreload.py", line 54, in wrapper
    fn(*args, **kwargs)
  File "/Users/mac/Desktop/sa-manage/super/lib/python3.7/site-packages/django/__init__.py", line 24, in setup
    apps.populate(settings.INSTALLED_APPS)
  File "/Users/mac/Desktop/sa-manage/super/lib/python3.7/site-packages/django/apps/registry.py", line 114, in populate
    app_config.import_models()
  File "/Users/mac/Desktop/sa-manage/super/lib/python3.7/site-packages/django/apps/config.py", line 211, in import_models
    self.models_module = import_module(models_module_name)
  File "/Users/mac/Desktop/sa-manage/super/lib/python3.7/importlib/__init__.py", line 127, in import_module
    return _bootstrap._gcd_import(name[level:], package, level)
  File "<frozen importlib._bootstrap>", line 1006, in _gcd_import
  File "<frozen importlib._bootstrap>", line 983, in _find_and_load
  File "<frozen importlib._bootstrap>", line 967, in _find_and_load_unlocked
  File "<frozen importlib._bootstrap>", line 677, in _load_unlocked
  File "<frozen importlib._bootstrap_external>", line 728, in exec_module
  File "<frozen importlib._bootstrap>", line 219, in _call_with_frames_removed
  File "/Users/mac/Desktop/sa-manage/super/signature/apple/models.py", line 4, in <module>
    class AppleAccountTb(models.Model):
  File "/Users/mac/Desktop/sa-manage/super/signature/apple/models.py", line 16, in AppleAccountTb
    create_time = models.DateTimeField("生成的日期", default=timezone.now)
NameError: name 'timezone' is not defined

Exception in thread django-main-thread:
Traceback (most recent call last):
  File "/usr/local/Cellar/python/3.7.5/Frameworks/Python.framework/Versions/3.7/lib/python3.7/threading.py", line 926, in _bootstrap_inner
    self.run()
  File "/usr/local/Cellar/python/3.7.5/Frameworks/Python.framework/Versions/3.7/lib/python3.7/threading.py", line 870, in run
    self._target(*self._args, **self._kwargs)
  File "/Users/mac/Desktop/sa-manage/super/lib/python3.7/site-packages/django/utils/autoreload.py", line 54, in wrapper
    fn(*args, **kwargs)
  File "/Users/mac/Desktop/sa-manage/super/lib/python3.7/site-packages/django/core/management/commands/runserver.py", line 109, in inner_run
    autoreload.raise_last_exception()
  File "/Users/mac/Desktop/sa-manage/super/lib/python3.7/site-packages/django/utils/autoreload.py", line 77, in raise_last_exception
    raise _exception[1]
  File "/Users/mac/Desktop/sa-manage/super/lib/python3.7/site-packages/django/core/management/__init__.py", line 337, in execute
    autoreload.check_errors(django.setup)()
  File "/Users/mac/Desktop/sa-manage/super/lib/python3.7/site-packages/django/utils/autoreload.py", line 54, in wrapper
    fn(*args, **kwargs)
  File "/Users/mac/Desktop/sa-manage/super/lib/python3.7/site-packages/django/__init__.py", line 24, in setup
    apps.populate(settings.INSTALLED_APPS)
  File "/Users/mac/Desktop/sa-manage/super/lib/python3.7/site-packages/django/apps/registry.py", line 114, in populate
    app_config.import_models()
  File "/Users/mac/Desktop/sa-manage/super/lib/python3.7/site-packages/django/apps/config.py", line 211, in import_models
    self.models_module = import_module(models_module_name)
  File "/Users/mac/Desktop/sa-manage/super/lib/python3.7/importlib/__init__.py", line 127, in import_module
    return _bootstrap._gcd_import(name[level:], package, level)
  File "<frozen importlib._bootstrap>", line 1006, in _gcd_import
  File "<frozen importlib._bootstrap>", line 983, in _find_and_load
  File "<frozen importlib._bootstrap>", line 967, in _find_and_load_unlocked
  File "<frozen importlib._bootstrap>", line 677, in _load_unlocked
  File "<frozen importlib._bootstrap_external>", line 728, in exec_module
  File "<frozen importlib._bootstrap>", line 219, in _call_with_frames_removed
  File "/Users/mac/Desktop/sa-manage/super/signature/apple/models.py", line 4, in <module>
    class AppleAccountTb(models.Model):
  File "/Users/mac/Desktop/sa-manage/super/signature/apple/models.py", line 16, in AppleAccountTb
    create_time = models.DateTimeField("生成的日期", default=timezone.now)
NameError: name 'timezone' is not defined

Exception in thread django-main-thread:
Traceback (most recent call last):
  File "/usr/local/Cellar/python/3.7.5/Frameworks/Python.framework/Versions/3.7/lib/python3.7/threading.py", line 926, in _bootstrap_inner
    self.run()
  File "/usr/local/Cellar/python/3.7.5/Frameworks/Python.framework/Versions/3.7/lib/python3.7/threading.py", line 870, in run
    self._target(*self._args, **self._kwargs)
  File "/Users/mac/Desktop/sa-manage/super/lib/python3.7/site-packages/django/utils/autoreload.py", line 54, in wrapper
    fn(*args, **kwargs)
  File "/Users/mac/Desktop/sa-manage/super/lib/python3.7/site-packages/django/core/management/commands/runserver.py", line 109, in inner_run
    autoreload.raise_last_exception()
  File "/Users/mac/Desktop/sa-manage/super/lib/python3.7/site-packages/django/utils/autoreload.py", line 77, in raise_last_exception
    raise _exception[1]
  File "/Users/mac/Desktop/sa-manage/super/lib/python3.7/site-packages/django/core/management/__init__.py", line 337, in execute
    autoreload.check_errors(django.setup)()
  File "/Users/mac/Desktop/sa-manage/super/lib/python3.7/site-packages/django/utils/autoreload.py", line 54, in wrapper
    fn(*args, **kwargs)
  File "/Users/mac/Desktop/sa-manage/super/lib/python3.7/site-packages/django/__init__.py", line 24, in setup
    apps.populate(settings.INSTALLED_APPS)
  File "/Users/mac/Desktop/sa-manage/super/lib/python3.7/site-packages/django/apps/registry.py", line 114, in populate
    app_config.import_models()
  File "/Users/mac/Desktop/sa-manage/super/lib/python3.7/site-packages/django/apps/config.py", line 211, in import_models
    self.models_module = import_module(models_module_name)
  File "/Users/mac/Desktop/sa-manage/super/lib/python3.7/importlib/__init__.py", line 127, in import_module
    return _bootstrap._gcd_import(name[level:], package, level)
  File "<frozen importlib._bootstrap>", line 1006, in _gcd_import
  File "<frozen importlib._bootstrap>", line 983, in _find_and_load
  File "<frozen importlib._bootstrap>", line 967, in _find_and_load_unlocked
  File "<frozen importlib._bootstrap>", line 677, in _load_unlocked
  File "<frozen importlib._bootstrap_external>", line 728, in exec_module
  File "<frozen importlib._bootstrap>", line 219, in _call_with_frames_removed
  File "/Users/mac/Desktop/sa-manage/super/signature/apple/models.py", line 4, in <module>
    class AppleAccountTb(models.Model):
  File "/Users/mac/Desktop/sa-manage/super/signature/apple/models.py", line 16, in AppleAccountTb
    create_time = models.DateTimeField("生成的日期", default=timezone.now)
NameError: name 'timezone' is not defined

Exception in thread django-main-thread:
Traceback (most recent call last):
  File "/usr/local/Cellar/python/3.7.5/Frameworks/Python.framework/Versions/3.7/lib/python3.7/threading.py", line 926, in _bootstrap_inner
    self.run()
  File "/usr/local/Cellar/python/3.7.5/Frameworks/Python.framework/Versions/3.7/lib/python3.7/threading.py", line 870, in run
    self._target(*self._args, **self._kwargs)
  File "/Users/mac/Desktop/sa-manage/super/lib/python3.7/site-packages/django/utils/autoreload.py", line 54, in wrapper
    fn(*args, **kwargs)
  File "/Users/mac/Desktop/sa-manage/super/lib/python3.7/site-packages/django/core/management/commands/runserver.py", line 109, in inner_run
    autoreload.raise_last_exception()
  File "/Users/mac/Desktop/sa-manage/super/lib/python3.7/site-packages/django/utils/autoreload.py", line 77, in raise_last_exception
    raise _exception[1]
  File "/Users/mac/Desktop/sa-manage/super/lib/python3.7/site-packages/django/core/management/__init__.py", line 337, in execute
    autoreload.check_errors(django.setup)()
  File "/Users/mac/Desktop/sa-manage/super/lib/python3.7/site-packages/django/utils/autoreload.py", line 54, in wrapper
    fn(*args, **kwargs)
  File "/Users/mac/Desktop/sa-manage/super/lib/python3.7/site-packages/django/__init__.py", line 24, in setup
    apps.populate(settings.INSTALLED_APPS)
  File "/Users/mac/Desktop/sa-manage/super/lib/python3.7/site-packages/django/apps/registry.py", line 114, in populate
    app_config.import_models()
  File "/Users/mac/Desktop/sa-manage/super/lib/python3.7/site-packages/django/apps/config.py", line 211, in import_models
    self.models_module = import_module(models_module_name)
  File "/Users/mac/Desktop/sa-manage/super/lib/python3.7/importlib/__init__.py", line 127, in import_module
    return _bootstrap._gcd_import(name[level:], package, level)
  File "<frozen importlib._bootstrap>", line 1006, in _gcd_import
  File "<frozen importlib._bootstrap>", line 983, in _find_and_load
  File "<frozen importlib._bootstrap>", line 967, in _find_and_load_unlocked
  File "<frozen importlib._bootstrap>", line 677, in _load_unlocked
  File "<frozen importlib._bootstrap_external>", line 728, in exec_module
  File "<frozen importlib._bootstrap>", line 219, in _call_with_frames_removed
  File "/Users/mac/Desktop/sa-manage/super/signature/apple/models.py", line 4, in <module>
    class AppleAccountTb(models.Model):
  File "/Users/mac/Desktop/sa-manage/super/signature/apple/models.py", line 16, in AppleAccountTb
    create_time = models.DateTimeField("生成的日期", default=timezone.now)
NameError: name 'timezone' is not defined

Exception in thread django-main-thread:
Traceback (most recent call last):
  File "/usr/local/Cellar/python/3.7.5/Frameworks/Python.framework/Versions/3.7/lib/python3.7/threading.py", line 926, in _bootstrap_inner
    self.run()
  File "/usr/local/Cellar/python/3.7.5/Frameworks/Python.framework/Versions/3.7/lib/python3.7/threading.py", line 870, in run
    self._target(*self._args, **self._kwargs)
  File "/Users/mac/Desktop/sa-manage/super/lib/python3.7/site-packages/django/utils/autoreload.py", line 54, in wrapper
    fn(*args, **kwargs)
  File "/Users/mac/Desktop/sa-manage/super/lib/python3.7/site-packages/django/core/management/commands/runserver.py", line 109, in inner_run
    autoreload.raise_last_exception()
  File "/Users/mac/Desktop/sa-manage/super/lib/python3.7/site-packages/django/utils/autoreload.py", line 77, in raise_last_exception
    raise _exception[1]
  File "/Users/mac/Desktop/sa-manage/super/lib/python3.7/site-packages/django/core/management/__init__.py", line 337, in execute
    autoreload.check_errors(django.setup)()
  File "/Users/mac/Desktop/sa-manage/super/lib/python3.7/site-packages/django/utils/autoreload.py", line 54, in wrapper
    fn(*args, **kwargs)
  File "/Users/mac/Desktop/sa-manage/super/lib/python3.7/site-packages/django/__init__.py", line 24, in setup
    apps.populate(settings.INSTALLED_APPS)
  File "/Users/mac/Desktop/sa-manage/super/lib/python3.7/site-packages/django/apps/registry.py", line 114, in populate
    app_config.import_models()
  File "/Users/mac/Desktop/sa-manage/super/lib/python3.7/site-packages/django/apps/config.py", line 211, in import_models
    self.models_module = import_module(models_module_name)
  File "/Users/mac/Desktop/sa-manage/super/lib/python3.7/importlib/__init__.py", line 127, in import_module
    return _bootstrap._gcd_import(name[level:], package, level)
  File "<frozen importlib._bootstrap>", line 1006, in _gcd_import
  File "<frozen importlib._bootstrap>", line 983, in _find_and_load
  File "<frozen importlib._bootstrap>", line 967, in _find_and_load_unlocked
  File "<frozen importlib._bootstrap>", line 677, in _load_unlocked
  File "<frozen importlib._bootstrap_external>", line 728, in exec_module
  File "<frozen importlib._bootstrap>", line 219, in _call_with_frames_removed
  File "/Users/mac/Desktop/sa-manage/super/signature/apple/models.py", line 5, in <module>
    class AppleAccountTb(models.Model):
  File "/Users/mac/Desktop/sa-manage/super/signature/apple/models.py", line 17, in AppleAccountTb
    create_time = models.DateTimeField("生成的日期", default=timezone.now)
NameError: name 'timezone' is not defined

Exception in thread django-main-thread:
Traceback (most recent call last):
  File "/usr/local/Cellar/python/3.7.5/Frameworks/Python.framework/Versions/3.7/lib/python3.7/threading.py", line 926, in _bootstrap_inner
    self.run()
  File "/usr/local/Cellar/python/3.7.5/Frameworks/Python.framework/Versions/3.7/lib/python3.7/threading.py", line 870, in run
    self._target(*self._args, **self._kwargs)
  File "/Users/mac/Desktop/sa-manage/super/lib/python3.7/site-packages/django/utils/autoreload.py", line 54, in wrapper
    fn(*args, **kwargs)
  File "/Users/mac/Desktop/sa-manage/super/lib/python3.7/site-packages/django/core/management/commands/runserver.py", line 109, in inner_run
    autoreload.raise_last_exception()
  File "/Users/mac/Desktop/sa-manage/super/lib/python3.7/site-packages/django/utils/autoreload.py", line 77, in raise_last_exception
    raise _exception[1]
  File "/Users/mac/Desktop/sa-manage/super/lib/python3.7/site-packages/django/core/management/__init__.py", line 337, in execute
    autoreload.check_errors(django.setup)()
  File "/Users/mac/Desktop/sa-manage/super/lib/python3.7/site-packages/django/utils/autoreload.py", line 54, in wrapper
    fn(*args, **kwargs)
  File "/Users/mac/Desktop/sa-manage/super/lib/python3.7/site-packages/django/__init__.py", line 24, in setup
    apps.populate(settings.INSTALLED_APPS)
  File "/Users/mac/Desktop/sa-manage/super/lib/python3.7/site-packages/django/apps/registry.py", line 114, in populate
    app_config.import_models()
  File "/Users/mac/Desktop/sa-manage/super/lib/python3.7/site-packages/django/apps/config.py", line 211, in import_models
    self.models_module = import_module(models_module_name)
  File "/Users/mac/Desktop/sa-manage/super/lib/python3.7/importlib/__init__.py", line 127, in import_module
    return _bootstrap._gcd_import(name[level:], package, level)
  File "<frozen importlib._bootstrap>", line 1006, in _gcd_import
  File "<frozen importlib._bootstrap>", line 983, in _find_and_load
  File "<frozen importlib._bootstrap>", line 967, in _find_and_load_unlocked
  File "<frozen importlib._bootstrap>", line 677, in _load_unlocked
  File "<frozen importlib._bootstrap_external>", line 728, in exec_module
  File "<frozen importlib._bootstrap>", line 219, in _call_with_frames_removed
  File "/Users/mac/Desktop/sa-manage/super/signature/apple/models.py", line 5, in <module>
    class AppleAccountTb(models.Model):
  File "/Users/mac/Desktop/sa-manage/super/signature/apple/models.py", line 17, in AppleAccountTb
    create_time = models.DateTimeField("生成的日期", default=timezone.now)
NameError: name 'timezone' is not defined

Performing system checks...

System check identified no issues (0 silenced).
January 11, 2020 - 09:45:48
Django version 2.2.5, using settings 'signature.settings'
Starting ASGI/Channels version 2.1.7 development server at http://127.0.0.1:5001/
Quit the server with CONTROL-C.
Performing system checks...

System check identified no issues (0 silenced).
January 11, 2020 - 09:46:11
Django version 2.2.5, using settings 'signature.settings'
Starting ASGI/Channels version 2.1.7 development server at http://127.0.0.1:5001/
Quit the server with CONTROL-C.
Performing system checks...

System check identified no issues (0 silenced).
January 11, 2020 - 09:46:51
Django version 2.2.5, using settings 'signature.settings'
Starting ASGI/Channels version 2.1.7 development server at http://127.0.0.1:5001/
Quit the server with CONTROL-C.
Performing system checks...

System check identified no issues (0 silenced).
January 11, 2020 - 09:48:34
Django version 2.2.5, using settings 'signature.settings'
Starting ASGI/Channels version 2.1.7 development server at http://127.0.0.1:5001/
Quit the server with CONTROL-C.
Performing system checks...

System check identified no issues (0 silenced).
January 11, 2020 - 09:48:45
Django version 2.2.5, using settings 'signature.settings'
Starting ASGI/Channels version 2.1.7 development server at http://127.0.0.1:5001/
Quit the server with CONTROL-C.
Performing system checks...

System check identified no issues (0 silenced).
January 11, 2020 - 09:48:50
Django version 2.2.5, using settings 'signature.settings'
Starting ASGI/Channels version 2.1.7 development server at http://127.0.0.1:5001/
Quit the server with CONTROL-C.
Performing system checks...

System check identified no issues (0 silenced).
January 11, 2020 - 09:57:23
Django version 2.2.5, using settings 'signature.settings'
Starting ASGI/Channels version 2.1.7 development server at http://127.0.0.1:5001/
Quit the server with CONTROL-C.
Performing system checks...

System check identified no issues (0 silenced).
January 11, 2020 - 09:59:40
Django version 2.2.5, using settings 'signature.settings'
Starting ASGI/Channels version 2.1.7 development server at http://127.0.0.1:5001/
Quit the server with CONTROL-C.
Performing system checks...

System check identified no issues (0 silenced).
January 11, 2020 - 10:01:27
Django version 2.2.5, using settings 'signature.settings'
Starting ASGI/Channels version 2.1.7 development server at http://127.0.0.1:5001/
Quit the server with CONTROL-C.
Performing system checks...

System check identified no issues (0 silenced).
January 11, 2020 - 10:03:42
Django version 2.2.5, using settings 'signature.settings'
Starting ASGI/Channels version 2.1.7 development server at http://127.0.0.1:5001/
Quit the server with CONTROL-C.
